<?xml version="1.0" ?>
<sdf version="1.9">
    <model name='Crawler' canonical_link='base_link'>

      <frame name="caster_frame1" attached_to='base_link'>
        <pose>0.4 0 -0.1 0 0 0</pose>  
      </frame>
      <frame name="caster_frame2" attached_to='base_link'>
        <pose>-0.4 0 -0.1 0 0 0</pose>  
      </frame>

      <link name='base_link'>
        <pose relative_to='__model__'>0 0 0.2 0 0 0</pose>  
        <inertial>
          <mass>2</mass>
          <inertia>
            <ixx>0.0520833</ixx>
            <ixy>0</ixy>
            <ixz>0</ixz>
            <iyy>0.1760417</iyy>
            <iyz>0</iyz>
            <izz>0.2083333</izz>
          </inertia>
        </inertial>
        <visual name='base_link_visual'>
          <geometry>
            <box>
              <size>1.0 0.5 0.25</size> 
            </box>
          </geometry>
          <material>
            <ambient>0.0 0.0 1.0 1</ambient>
            <diffuse>0.0 0.0 1.0 1</diffuse>
            <specular>0.0 0.0 1.0 1</specular>
          </material>
        </visual>
        <collision name='collision'>
          <geometry>
            <box>
              <size>1.0 0.5 0.25</size>  <!-- Halved size -->
            </box>
          </geometry>
        </collision>
        <sensor name="IMU" type="imu">
          <always_on>1</always_on>
          <update_rate>30</update_rate>
          <visualize>true</visualize>
          <topic>imu</topic>
          <imu>
            <angular_velocity>
              <x>
                <noise type='gaussian'>
                  <mean>0</mean>
                  <stddev>0.001</stddev>
                </noise>
              </x>
              <y>
                <noise type='gaussian'>
                  <mean>0</mean>
                  <stddev>0.001</stddev>
                </noise>
              </y>
              <z>
                <noise type='none' />
              </z>
            </angular_velocity>
            <linear_acceleration>
              <x>
                <noise type='gaussian'>
                  <mean>0</mean>
                  <stddev>0.0005</stddev>
                </noise>
              </x>
              <y>
                <noise type='gaussian'>
                  <mean>0</mean>
                  <stddev>0.0005</stddev>
                </noise>
              </y>
              <z>
                <noise type='none' />
              </z>
            </linear_acceleration>
            <enable_orientation>true</enable_orientation>
          </imu>
        </sensor>

        <sensor name='LinSense' type='gpu_lidar'>
          <pose relative_to='base_link'>0 0 0.25 0 0 0</pose>
          <topic>scan_lid</topic>
          <ray>
            <scan>
              <horizontal>
                <samples>360</samples>
                <resolution>1</resolution>
                <min_angle>-3.14159</min_angle> 
                <max_angle>3.14159</max_angle> 
              </horizontal>
            </scan>
            <range>
              <min>0.1</min>
              <max>10.0</max>
            </range>
          </ray>
          <visualize>true</visualize> 
          <update_rate>30</update_rate>
          <always_on>1</always_on>
          <noise>
            <type>gaussian_noise</type>
            <mean>0</mean>
            <stddev>0.01</stddev>
          </noise>
        </sensor>
        
      </link>
       <link name='base_footprint'>
        <pose relative_to='base_link'>0 0 -0.2 0 0 0</pose>
      </link>
  
      <link name='left_wheel'>
        <pose relative_to='base_link'>0 0.3 0 -1.5707 0 0</pose>  
        <inertial>
          <mass>2</mass>
          <inertia>
            <ixx>0.01667</ixx>  
            <ixy>0</ixy>
            <ixz>0</ixz>
            <iyy>0.01667</iyy>  
            <iyz>0</iyz>
            <izz>0.004</izz>  
          </inertia>
        </inertial>

        <visual name='visual'>
          <geometry>
            <cylinder>
              <radius>0.2</radius>  
              <length>0.1</length>  
            </cylinder>
          </geometry>
          <material>
            <ambient>1.0 0.0 0.0 1</ambient>
            <diffuse>1.0 0.0 0.0 1</diffuse>
            <specular>1.0 0.0 0.0 1</specular>
          </material>
        </visual>

        <collision name='collision'>
          <geometry>
            <cylinder>
              <radius>0.2</radius>  
              <length>0.1</length> 
            </cylinder>
          </geometry>
        </collision>
      </link>

      <link name='right_wheel'>
        <pose relative_to="base_link">0 -0.3 0 -1.5707 0 0</pose>  
        <inertial>
        <mass>2</mass>
        <inertia>
          <ixx>0.01667</ixx>  
          <ixy>0</ixy>
          <ixz>0</ixz>
          <iyy>0.01667</iyy>  
          <iyz>0</iyz>
          <izz>0.004</izz>  
        </inertia>
      </inertial>

        <visual name='visual'>
          <geometry>
            <cylinder>
              <radius>0.2</radius>  
              <length>0.1</length>  
            </cylinder>
          </geometry>
          <material>
            <ambient>1.0 0.0 0.0 1</ambient>
            <diffuse>1.0 0.0 0.0 1</diffuse>
            <specular>1.0 0.0 0.0 1</specular>
          </material>
        </visual>

        <collision name='collision'>
          <geometry>
            <cylinder>
              <radius>0.2</radius>  
              <length>0.1</length>  
            </cylinder>
          </geometry>
        </collision>
      </link>

      <link name='caster1'>
        <pose relative_to='caster_frame1'/>
        <inertial>
          <mass>2</mass>
          <inertia>
            <ixx>0.004</ixx>
            <ixy>0</ixy>
            <ixz>0</ixz>
            <iyy>0.004</iyy>
            <iyz>0</iyz>
            <izz>0.004</izz>
          </inertia>
        </inertial>

        <visual name='visual'>
            <geometry>
                <sphere>
                    <radius>0.1</radius>  
                </sphere>
            </geometry>
            <material>
                <ambient>0.0 1 0.0 1</ambient>
                <diffuse>0.0 1 0.0 1</diffuse>
                <specular>0.0 1 0.0 1</specular>
            </material>
        </visual>

        <collision name='collision'>
            <geometry>
                <sphere>
                    <radius>0.1</radius>  
                </sphere>
            </geometry>
        </collision>
      </link>


      <link name='caster2'>
        <pose relative_to='caster_frame2'/>
        <inertial>
          <mass>2</mass>
          <inertia>
            <ixx>0.004</ixx>
            <ixy>0</ixy>
            <ixz>0</ixz>
            <iyy>0.004</iyy>
            <iyz>0</iyz>
            <izz>0.004</izz>
          </inertia>
        </inertial>

        <visual name='visual'>
            <geometry>
                <sphere>
                    <radius>0.1</radius>  
                </sphere>
            </geometry>
            <material>
                <ambient>0.0 1 0.0 1</ambient>
                <diffuse>0.0 1 0.0 1</diffuse>
                <specular>0.0 1 0.0 1</specular>
            </material>
        </visual>

        <collision name='collision'>
            <geometry>
                <sphere>
                    <radius>0.1</radius>  
                </sphere>
            </geometry>
        </collision>
      </link>

      <joint name='left_wheel_joint' type='revolute'>
        <parent>base_link</parent>
        <child>left_wheel</child>
        <axis>
            <xyz expressed_in='__model__'>0 1 0</xyz>
            <limit>
                <lower>-1.79769e+308</lower>
                <upper>1.79769e+308</upper>
            </limit>
        </axis>
      </joint>

      <joint name='right_wheel_joint' type='revolute'>
        <parent>base_link</parent>
        <child>right_wheel</child>
        <axis>
            <xyz expressed_in='__model__'>0 1 0</xyz>
            <limit>
                <lower>-1.79769e+308</lower>
                <upper>1.79769e+308</upper>
            </limit>
        </axis>
      </joint>

      <joint name='caster_wheel1' type='ball'>
        <parent>base_link</parent>
        <child>caster1</child>
      </joint>

      <joint name='caster_wheel2' type='ball'>
        <parent>base_link</parent>
        <child>caster2</child>
      </joint>

      <joint name='base_footprint_joint' type='fixed'>
        <parent>base_link</parent>
        <child>base_footprint</child>
      </joint>

      <plugin 
        filename="libignition-gazebo-diff-drive-system.so" 
        name="ignition::gazebo::systems::DiffDrive">
        <left_joint>left_wheel_joint</left_joint>
        <right_joint>right_wheel_joint</right_joint>
        <wheel_separation>0.6</wheel_separation>
        <wheel_radius>0.2</wheel_radius>
        <topic>cmd_vel</topic>
        <robotBaseFrame>base_link</robotBaseFrame>
        <odometryFrame>odom</odometryFrame>
        <odometrySource>1</odometrySource>
      </plugin>

      <plugin
          filename="ignition-gazebo-odometry-publisher-system"
          name="ignition::gazebo::systems::OdometryPublisher">
          <odom_frame>odom</odom_frame>
          <robot_base_frame>base_link</robot_base_frame>
          <odom_topic>odom</odom_topic>
          <odom_publish_frequency>100</odom_publish_frequency>
          <odom_covariance_topic>odom_cv</odom_covariance_topic>
          <gaussian_noise>0.02</gaussian_noise>
      </plugin>


      <plugin
        filename="ignition-gazebo-joint-state-publisher-system"
        name="ignition::gazebo::systems::JointStatePublisher">
         <publish_link_pose>true</publish_link_pose>
        <use_pose_vector_msg>true</use_pose_vector_msg>
      </plugin>

      <plugin filename="libignition-gazebo-triggered-publisher-system.so"
        name="ignition::gazebo::systems::TriggeredPublisher">
        <input type="ignition.msgs.Int32" topic="/keyboard/keypress">
        <match field="data">16777235</match>
        </input>
        <output type="ignition.msgs.Twist" topic="/cmd_vel">
        linear: {x: 1.0}, angular: {z: 0.0}
        </output>
      </plugin>
      <plugin filename="libignition-gazebo-triggered-publisher-system.so"
        name="ignition::gazebo::systems::TriggeredPublisher">
        <input type="ignition.msgs.Int32" topic="/keyboard/keypress">
        <match field="data">16777237</match>
        </input>
        <output type="ignition.msgs.Twist" topic="/cmd_vel">
        linear: {x: -1.0}, angular: {z: 0.0}
        </output>
      </plugin>
      <plugin filename="libignition-gazebo-triggered-publisher-system.so"
        name="ignition::gazebo::systems::TriggeredPublisher">
        <input type="ignition.msgs.Int32" topic="/keyboard/keypress">
        <match field="data">16777234</match>
        </input>
        <output type="ignition.msgs.Twist" topic="/cmd_vel">
        linear: {x: 0.0}, angular: {z: 1.0}
        </output>
      </plugin>
      <plugin filename="libignition-gazebo-triggered-publisher-system.so"
        name="ignition::gazebo::systems::TriggeredPublisher">
        <input type="ignition.msgs.Int32" topic="/keyboard/keypress">
        <match field="data">16777236</match>
        </input>
        <output type="ignition.msgs.Twist" topic="/cmd_vel">
        linear: {x: 0.0}, angular: {z: -1.0}
        </output>
      </plugin>
      <plugin filename="libignition-gazebo-triggered-publisher-system.so"
        name="ignition::gazebo::systems::TriggeredPublisher">
        <input type="ignition.msgs.Int32" topic="/keyboard/keypress">
        <match field="data">88</match>
        </input>
        <output type="ignition.msgs.Twist" topic="/cmd_vel">
        linear: {x: 0.0}, angular: {z: 0.0}
        </output>
      </plugin>
    </model>
</sdf>